Workbook

Sheet Start Here
A1: Advanced Excel Practice Workbook
A2: Companion to the Advanced Excel Walkthrough Guide. Each tab matches a guide topic with the same numbers.
A4: Colour legend
A5: Blue text on pale yellow = an input you can change.
A6: Black text = a formula. Green text = a formula that pulls from another sheet.
A7: Bright yellow cells = empty on purpose: you build that part (the guide shows how).
A8: Pale green cells = answer checks, so you can confirm your result.
A9: Brown text = a formula shown as text for you to read or type yourself.
A11: Sheet | B11: Guide topic | C11: What you practise
A12: Data | B12: Shared sales data | C12: 20 orders used by most other sheets; price and category are looked up
A13: 1 Charts | B13: 1. Charting | C13: Column, pie and combo charts built from summary formulas
A14: 2 Dates | B14: 2. Date and time functions | C14: TODAY, DATE, EDATE, EOMONTH, NETWORKDAYS, DATEDIF, time maths
A15: 3 PivotTables | B15: 3. PivotTables | C15: Build a PivotTable from Data and check it against SUMIFS
A16: 4 External Data | B16: 4. Internal and external data | C16: Clean imported text, import the CSV, Tables and structured references
A17: 5 Sort Filter | B17: 5. Sorting and filtering | C17: Multi-level sort, AutoFilter, Advanced Filter with a criteria range
A18: 6 Lookup Query | B18: 6. Extracting and querying | C18: VLOOKUP, INDEX/MATCH, two-way lookup, DSUM and friends
A19: 7 Multi-Sheet | B19: 7. Multiple worksheets and workbooks | C19: 3-D references across Jan, Feb, Mar and external link syntax
A20: 8 Auditing | B20: 8. Formula auditing | C20: Trace arrows, error types and fixes, a bug hunt
A21: 9 Input Control | B21: 9. Controlling user input | C21: Data validation rules, input messages, unlocked cells, protection
A22: 10 Financial | B22: 10. Financial functions | C22: PMT, IPMT, PPMT, FV, PV, NPV, IRR, RATE, NPER, SLN, amortization
... A27: 15 Macros | B27: 15. Macros | C27: Record a macro and paste three short VBA procedures
A29: Notes
A30: Example data is invented for teaching (Jan-May 2026 orders for a small office-supply seller).
A31: Macros cannot live in an .xlsx file. On the Macros tab you save a copy as .xlsm before recording.
A32: PivotTables, data tables, scenarios and Solver runs are left for you to perform; every one has an answer check.

Sheet Data
A1: Sales data (shared by the other sheets)
A2: An Excel Table named SalesData. Category and Unit Price are looked up from the product list on the right.
A4: Date | B4: Region | C4: Rep | D4: Product | E4: Category | F4: Units | G4: Unit Price | H4: Revenue | K4: Product | L4: Category | M4: Unit Price
A5: 46027 | B5: East | C5: Avery | D5: Laptop | E5: =VLOOKUP(D5,$K$5:$M$9,2,FALSE()) -> Hardware | F5: 4 | G5: =VLOOKUP(D5,$K$5:$M$9,3,FALSE()) -> 900 | H5: =F5*G5 -> 3600 | K5: Laptop | L5: Hardware | M5: 900
A6: 46034 | B6: West | C6: Blake | D6: Monitor | E6: =VLOOKUP(D6,$K$5:$M$9,2,FALSE()) -> Hardware | F6: 10 | G6: =VLOOKUP(D6,$K$5:$M$9,3,FALSE()) -> 250 | H6: =F6*G6 -> 2500 | K6: Monitor | L6: Hardware | M6: 250
A7: 46041 | B7: North | C7: Casey | D7: Keyboard | E7: =VLOOKUP(D7,$K$5:$M$9,2,FALSE()) -> Accessories | F7: 25 | G7: =VLOOKUP(D7,$K$5:$M$9,3,FALSE()) -> 40 | H7: =F7*G7 -> 1000 | K7: Keyboard | L7: Accessories | M7: 40
A8: 46048 | B8: South | C8: Devon | D8: Mouse | E8: =VLOOKUP(D8,$K$5:$M$9,2,FALSE()) -> Accessories | F8: 40 | G8: =VLOOKUP(D8,$K$5:$M$9,3,FALSE()) -> 25 | H8: =F8*G8 -> 1000 | K8: Mouse | L8: Accessories | M8: 25
A9: 46055 | B9: East | C9: Avery | D9: License | E9: =VLOOKUP(D9,$K$5:$M$9,2,FALSE()) -> Software | F9: 15 | G9: =VLOOKUP(D9,$K$5:$M$9,3,FALSE()) -> 120 | H9: =F9*G9 -> 1800 | K9: License | L9: Software | M9: 120
A10: 46062 | B10: West | C10: Blake | D10: Laptop | E10: =VLOOKUP(D10,$K$5:$M$9,2,FALSE()) -> Hardware | F10: 6 | G10: =VLOOKUP(D10,$K$5:$M$9,3,FALSE()) -> 900 | H10: =F10*G10 -> 5400
A11: 46069 | B11: North | C11: Casey | D11: Monitor | E11: =VLOOKUP(D11,$K$5:$M$9,2,FALSE()) -> Hardware | F11: 8 | G11: =VLOOKUP(D11,$K$5:$M$9,3,FALSE()) -> 250 | H11: =F11*G11 -> 2000 | K11: Product list: invented prices. Change one and every sheet updates.
A12: 46076 | B12: South | C12: Devon | D12: Keyboard | E12: =VLOOKUP(D12,$K$5:$M$9,2,FALSE()) -> Accessories | F12: 30 | G12: =VLOOKUP(D12,$K$5:$M$9,3,FALSE()) -> 40 | H12: =F12*G12 -> 1200
A13: 46083 | B13: East | C13: Avery | D13: Mouse | E13: =VLOOKUP(D13,$K$5:$M$9,2,FALSE()) -> Accessories | F13: 50 | G13: =VLOOKUP(D13,$K$5:$M$9,3,FALSE()) -> 25 | H13: =F13*G13 -> 1250
A14: 46090 | B14: West | C14: Blake | D14: License | E14: =VLOOKUP(D14,$K$5:$M$9,2,FALSE()) -> Software | F14: 20 | G14: =VLOOKUP(D14,$K$5:$M$9,3,FALSE()) -> 120 | H14: =F14*G14 -> 2400
A15: 46097 | B15: North | C15: Casey | D15: Laptop | E15: =VLOOKUP(D15,$K$5:$M$9,2,FALSE()) -> Hardware | F15: 3 | G15: =VLOOKUP(D15,$K$5:$M$9,3,FALSE()) -> 900 | H15: =F15*G15 -> 2700
A16: 46104 | B16: South | C16: Devon | D16: Monitor | E16: =VLOOKUP(D16,$K$5:$M$9,2,FALSE()) -> Hardware | F16: 12 | G16: =VLOOKUP(D16,$K$5:$M$9,3,FALSE()) -> 250 | H16: =F16*G16 -> 3000
A17: 46118 | B17: East | C17: Avery | D17: Keyboard | E17: =VLOOKUP(D17,$K$5:$M$9,2,FALSE()) -> Accessories | F17: 20 | G17: =VLOOKUP(D17,$K$5:$M$9,3,FALSE()) -> 40 | H17: =F17*G17 -> 800
A18: 46125 | B18: West | C18: Blake | D18: Mouse | E18: =VLOOKUP(D18,$K$5:$M$9,2,FALSE()) -> Accessories | F18: 35 | G18: =VLOOKUP(D18,$K$5:$M$9,3,FALSE()) -> 25 | H18: =F18*G18 -> 875
A19: 46132 | B19: North | C19: Casey | D19: License | E19: =VLOOKUP(D19,$K$5:$M$9,2,FALSE()) -> Software | F19: 10 | G19: =VLOOKUP(D19,$K$5:$M$9,3,FALSE()) -> 120 | H19: =F19*G19 -> 1200
A20: 46139 | B20: South | C20: Devon | D20: Laptop | E20: =VLOOKUP(D20,$K$5:$M$9,2,FALSE()) -> Hardware | F20: 5 | G20: =VLOOKUP(D20,$K$5:$M$9,3,FALSE()) -> 900 | H20: =F20*G20 -> 4500
A21: 46146 | B21: East | C21: Avery | D21: Monitor | E21: =VLOOKUP(D21,$K$5:$M$9,2,FALSE()) -> Hardware | F21: 9 | G21: =VLOOKUP(D21,$K$5:$M$9,3,FALSE()) -> 250 | H21: =F21*G21 -> 2250
A22: 46153 | B22: West | C22: Blake | D22: Keyboard | E22: =VLOOKUP(D22,$K$5:$M$9,2,FALSE()) -> Accessories | F22: 15 | G22: =VLOOKUP(D22,$K$5:$M$9,3,FALSE()) -> 40 | H22: =F22*G22 -> 600
A23: 46160 | B23: North | C23: Casey | D23: Mouse | E23: =VLOOKUP(D23,$K$5:$M$9,2,FALSE()) -> Accessories | F23: 60 | G23: =VLOOKUP(D23,$K$5:$M$9,3,FALSE()) -> 25 | H23: =F23*G23 -> 1500
A24: 46167 | B24: South | C24: Devon | D24: License | E24: =VLOOKUP(D24,$K$5:$M$9,2,FALSE()) -> Software | F24: 25 | G24: =VLOOKUP(D24,$K$5:$M$9,3,FALSE()) -> 120 | H24: =F24*G24 -> 3000
E26: Total | F26: =SUM(F5:F24) -> 402 | H26: =SUM(H5:H24) -> 42575

Sheet 1 Charts
A1: 1. Charting
A2: Guide topic 1. Charts read from the summary tables, which read from Data.
A4: Month start | B4: Label | C4: Revenue | D4: Units
A5: 46023 | B5: =TEXT(A5,"mmm") -> Jan | C5: =SUMIFS(Data!$H$5:$H$24,Data!$A$5:$A$24,">="&A5,Data!$A$5:$A$24,"<="&EOMONTH(A5,0)) -> 8100 | D5: =SUMIFS(Data!$F$5:$F$24,Data!$A$5:$A$24,">="&A5,Data!$A$5:$A$24,"<="&EOMONTH(A5,0)) -> 79
A6: 46054 | B6: =TEXT(A6,"mmm") -> Feb | C6: =SUMIFS(Data!$H$5:$H$24,Data!$A$5:$A$24,">="&A6,Data!$A$5:$A$24,"<="&EOMONTH(A6,0)) -> 10400 | D6: =SUMIFS(Data!$F$5:$F$24,Data!$A$5:$A$24,">="&A6,Data!$A$5:$A$24,"<="&EOMONTH(A6,0)) -> 59
A7: 46082 | B7: =TEXT(A7,"mmm") -> Mar | C7: =SUMIFS(Data!$H$5:$H$24,Data!$A$5:$A$24,">="&A7,Data!$A$5:$A$24,"<="&EOMONTH(A7,0)) -> 9350 | D7: =SUMIFS(Data!$F$5:$F$24,Data!$A$5:$A$24,">="&A7,Data!$A$5:$A$24,"<="&EOMONTH(A7,0)) -> 85
A8: 46113 | B8: =TEXT(A8,"mmm") -> Apr | C8: =SUMIFS(Data!$H$5:$H$24,Data!$A$5:$A$24,">="&A8,Data!$A$5:$A$24,"<="&EOMONTH(A8,0)) -> 7375 | D8: =SUMIFS(Data!$F$5:$F$24,Data!$A$5:$A$24,">="&A8,Data!$A$5:$A$24,"<="&EOMONTH(A8,0)) -> 70
A9: 46143 | B9: =TEXT(A9,"mmm") -> May | C9: =SUMIFS(Data!$H$5:$H$24,Data!$A$5:$A$24,">="&A9,Data!$A$5:$A$24,"<="&EOMONTH(A9,0)) -> 7350 | D9: =SUMIFS(Data!$F$5:$F$24,Data!$A$5:$A$24,">="&A9,Data!$A$5:$A$24,"<="&EOMONTH(A9,0)) -> 109
B10: Total | C10: =SUM(C5:C9) -> 42575 | D10: =SUM(D5:D9) -> 402
A13: Region | B13: Revenue | C13: Share
A14: East | B14: =SUMIFS(Data!$H$5:$H$24,Data!$B$5:$B$24,A14) -> 9700 | C14: =B14/$B$18 -> 0.22783324
A15: West | B15: =SUMIFS(Data!$H$5:$H$24,Data!$B$5:$B$24,A15) -> 11775 | C15: =B15/$B$18 -> 0.27657076
A16: North | B16: =SUMIFS(Data!$H$5:$H$24,Data!$B$5:$B$24,A16) -> 8400 | C16: =B16/$B$18 -> 0.19729888
A17: South | B17: =SUMIFS(Data!$H$5:$H$24,Data!$B$5:$B$24,A17) -> 12700 | C17: =B17/$B$18 -> 0.29829712
A18: Total | B18: =SUM(B14:B17) -> 42575
A21: Try it
A22: 1. Click the column chart, then Chart Design > Add Chart Element > Data Labels > Outside End.
A23: 2. Right-click the pie > Format Data Labels > tick Percentage.
A24: 3. Rebuild the combo yourself: select B4:D9 > Insert > Recommended Charts > All Charts > Combo,
A25: set Units to Line and tick Secondary Axis.
A26: 4. Change a Units value on the Data sheet and watch all three charts move.

Sheet 2 Dates
A1: 2. Date and time functions
A2: Guide topic 2. Excel stores a date as a serial number (days since Jan 0, 1900) and a time as a fraction of a day.
A4: Start date | B4: 46037
A5: End date | B5: 46303
A6: Clock in | B6: 0.35416667
A7: Clock out | B7: 0.71875
A9: What you want | B9: Formula | C9: Result | D9: How it works
A10: Today's date | B10: =TODAY() | C10: =TODAY() -> 46303 | D10: Volatile: updates every time the workbook recalculates
A11: Date and time right now | B11: =NOW() | C11: =NOW() -> 46303.778 | D11: Volatile; the decimal part is the time of day
A12: Build a date from parts | B12: =DATE(2026,12,25) | C12: =DATE(2026,12,25) -> 46381 | D12: Year, month, day. Safer than typing text dates
A13: Year of start date | B13: =YEAR(B4) | C13: =YEAR(B4) -> 2026 | D13: MONTH and DAY work the same way
A14: Month of start date | B14: =MONTH(B4) | C14: =MONTH(B4) -> 1
A15: Day of start date | B15: =DAY(B4) | C15: =DAY(B4) -> 15
A16: Serial number behind the start date | B16: =B4 | C16: =B4 -> 46037 | D16: Same cell, General format: the number Excel really stores
A17: Days between the two dates | B17: =B5-B4 | C17: =B5-B4 -> 266 | D17: Dates are numbers, so you can subtract them
A18: Whole months between | B18: =DATEDIF(B4,B5,"m") | C18: =DATEDIF(B4,B5,"m") -> 8 | D18: Hidden function: no tooltip appears. "y" years, "d" days
A19: Fraction of a year between | B19: =YEARFRAC(B4,B5) | C19: =YEARFRAC(B4,B5) -> 0.73055556 | D19: Used for interest and prorating
A20: Same day 3 months later | B20: =EDATE(B4,3) | C20: =EDATE(B4,3) -> 46127 | D20: Negative months go backwards
A21: Last day of the start month | B21: =EOMONTH(B4,0) | C21: =EOMONTH(B4,0) -> 46053 | D21: 0 = this month, 1 = next month
A22: Day-of-week number | B22: =WEEKDAY(B4) | C22: =WEEKDAY(B4) -> 5 | D22: 1 = Sunday ... 7 = Saturday by default
A23: Day name | B23: =TEXT(B4,"dddd") | C23: =TEXT(B4,"dddd") -> Thursday | D23: TEXT turns a date into formatted text
A24: Week number of the year | B24: =WEEKNUM(B4) | C24: =WEEKNUM(B4,1) -> 3
A25: Working days between (inclusive) | B25: =NETWORKDAYS(B4,B5) | C25: =NETWORKDAYS(B4,B5) -> 191 | D25: Skips Sat/Sun; add a holiday range as a 3rd argument
A26: Date 10 working days after start | B26: =WORKDAY(B4,10) | C26: =WORKDAY(B4,10) -> 46051 | D26: Good for due dates
A27: Hours worked | B27: =(B7-B6)*24 | C27: =(B7-B6)*24 -> 8.75 | D27: Time is a fraction of a day, so multiply by 24 for hours
A28: Hour of clock-in | B28: =HOUR(B6) | C28: =HOUR(B6) -> 8 | D28: MINUTE and SECOND work the same way
A29: Build a time from parts | B29: =TIME(14,30,0) | C29: =TIME(14,30,0) -> 0.60416667 | D29: Hour, minute, second

Sheet 3 PivotTables
A1: 3. PivotTables
A2: Guide topic 3. Build the PivotTable yourself, then compare it with the answer checks below.
A4: Build it
A5: 1. Go to the Data sheet and click any cell inside the table.
A6: 2. Insert > PivotTable > New Worksheet > OK.
A7: 3. Drag Region to Rows, Category to Columns, Revenue to Values.
A8: 4. Right-click a number > Number Format > Currency, 0 decimals.
A9: 5. Your grand total should be the same as E21 below.
A10: 6. Extra: drag Date to Rows above Region (Excel groups it by month); add a Slicer for Rep
A11: (PivotTable Analyze > Insert Slicer); double-click a number to drill down to its rows.
A12: 7. Change a Units value on Data, then PivotTable Analyze > Refresh. Pivots do not update on their own.
A15: Answer check 1: Sum of Revenue, Region by Category
A16: Region | B16: Hardware | C16: Accessories | D16: Software | E16: Grand Total
A17: East | B17: =SUMIFS(Data!$H$5:$H$24,Data!$B$5:$B$24,$A17,Data!$E$5:$E$24,B$16) -> 5850 | C17: =SUMIFS(Data!$H$5:$H$24,Data!$B$5:$B$24,$A17,Data!$E$5:$E$24,C$16) -> 2050 | D17: =SUMIFS(Data!$H$5:$H$24,Data!$B$5:$B$24,$A17,Data!$E$5:$E$24,D$16) -> 1800 | E17: =SUM(B17:D17) -> 9700
A18: West | B18: =SUMIFS(Data!$H$5:$H$24,Data!$B$5:$B$24,$A18,Data!$E$5:$E$24,B$16) -> 7900 | C18: =SUMIFS(Data!$H$5:$H$24,Data!$B$5:$B$24,$A18,Data!$E$5:$E$24,C$16) -> 1475 | D18: =SUMIFS(Data!$H$5:$H$24,Data!$B$5:$B$24,$A18,Data!$E$5:$E$24,D$16) -> 2400 | E18: =SUM(B18:D18) -> 11775
A19: North | B19: =SUMIFS(Data!$H$5:$H$24,Data!$B$5:$B$24,$A19,Data!$E$5:$E$24,B$16) -> 4700 | C19: =SUMIFS(Data!$H$5:$H$24,Data!$B$5:$B$24,$A19,Data!$E$5:$E$24,C$16) -> 2500 | D19: =SUMIFS(Data!$H$5:$H$24,Data!$B$5:$B$24,$A19,Data!$E$5:$E$24,D$16) -> 1200 | E19: =SUM(B19:D19) -> 8400
A20: South | B20: =SUMIFS(Data!$H$5:$H$24,Data!$B$5:$B$24,$A20,Data!$E$5:$E$24,B$16) -> 7500 | C20: =SUMIFS(Data!$H$5:$H$24,Data!$B$5:$B$24,$A20,Data!$E$5:$E$24,C$16) -> 2200 | D20: =SUMIFS(Data!$H$5:$H$24,Data!$B$5:$B$24,$A20,Data!$E$5:$E$24,D$16) -> 3000 | E20: =SUM(B20:D20) -> 12700
A21: Grand Total | B21: =SUM(B17:B20) -> 25950 | C21: =SUM(C17:C20) -> 8225 | D21: =SUM(D17:D20) -> 8400 | E21: =SUM(E17:E20) -> 42575
A24: Answer check 2: Rep in Rows; Revenue in Values three times (Count, Sum, Average)
A25: Rep | B25: Orders | C25: Total revenue | D25: Average order
A26: Avery | B26: =COUNTIFS(Data!$C$5:$C$24,A26) -> 5 | C26: =SUMIFS(Data!$H$5:$H$24,Data!$C$5:$C$24,A26) -> 9700 | D26: =AVERAGEIFS(Data!$H$5:$H$24,Data!$C$5:$C$24,A26) -> 1940
A27: Blake | B27: =COUNTIFS(Data!$C$5:$C$24,A27) -> 5 | C27: =SUMIFS(Data!$H$5:$H$24,Data!$C$5:$C$24,A27) -> 11775 | D27: =AVERAGEIFS(Data!$H$5:$H$24,Data!$C$5:$C$24,A27) -> 2355
A28: Casey | B28: =COUNTIFS(Data!$C$5:$C$24,A28) -> 5 | C28: =SUMIFS(Data!$H$5:$H$24,Data!$C$5:$C$24,A28) -> 8400 | D28: =AVERAGEIFS(Data!$H$5:$H$24,Data!$C$5:$C$24,A28) -> 1680
A29: Devon | B29: =COUNTIFS(Data!$C$5:$C$24,A29) -> 5 | C29: =SUMIFS(Data!$H$5:$H$24,Data!$C$5:$C$24,A29) -> 12700 | D29: =AVERAGEIFS(Data!$H$5:$H$24,Data!$C$5:$C$24,A29) -> 2540

Sheet 4 External Data
A1: 4. Working with internal and external data
A2: Guide topic 4. Part A cleans text that arrived from another system. Part B brings in the companion CSV file.
A4: Part A: clean imported text with formulas
A5: Raw text as imported | B5: Name | C5: Region | D5: Amount | E5: Technique
A6: avery|EAST|3,600 | B6: =PROPER(TRIM(LEFT(A6,FIND("|",A6)-1))) -> Avery | C6: =PROPER(TRIM(MID(A6,FIND("|",A6)+1,FIND("|",A6,FIND("|",A6)+1)-FIND("|",A6)-1))) -> East | D6: =VALUE(SUBSTITUTE(TRIM(MID(A6,FIND("|",A6,FIND("|",A6)+1)+1,20)),",","")) -> 3600 | E6: LEFT up to the first | then TRIM and PROPER
A7: BLAKE |west| 2,500 | B7: =PROPER(TRIM(LEFT(A7,FIND("|",A7)-1))) -> Blake | C7: =PROPER(TRIM(MID(A7,FIND("|",A7)+1,FIND("|",A7,FIND("|",A7)+1)-FIND("|",A7)-1))) -> West | D7: =VALUE(SUBSTITUTE(TRIM(MID(A7,FIND("|",A7,FIND("|",A7)+1)+1,20)),",","")) -> 2500 | E7: MID between the two | characters
A8: casey|North|1,000 | B8: =PROPER(TRIM(LEFT(A8,FIND("|",A8)-1))) -> Casey | C8: =PROPER(TRIM(MID(A8,FIND("|",A8)+1,FIND("|",A8,FIND("|",A8)+1)-FIND("|",A8)-1))) -> North | D8: =VALUE(SUBSTITUTE(TRIM(MID(A8,FIND("|",A8,FIND("|",A8)+1)+1,20)),",","")) -> 1000 | E8: MID after the second |, strip commas, VALUE to number
A9: devon |SOUTH|1,000 | B9: =PROPER(TRIM(LEFT(A9,FIND("|",A9)-1))) -> Devon | C9: =PROPER(TRIM(MID(A9,FIND("|",A9)+1,FIND("|",A9,FIND("|",A9)+1)-FIND("|",A9)-1))) -> South | D9: =VALUE(SUBSTITUTE(TRIM(MID(A9,FIND("|",A9,FIND("|",A9)+1)+1,20)),",","")) -> 1000
A10: Avery|east| 1,800 | B10: =PROPER(TRIM(LEFT(A10,FIND("|",A10)-1))) -> Avery | C10: =PROPER(TRIM(MID(A10,FIND("|",A10)+1,FIND("|",A10,FIND("|",A10)+1)-FIND("|",A10)-1))) -> East | D10: =VALUE(SUBSTITUTE(TRIM(MID(A10,FIND("|",A10,FIND("|",A10)+1)+1,20)),",","")) -> 1800
C11: Total | D11: =SUM(D6:D10) -> 9900
A13: Text to Columns
A14: Faster for one-off jobs: select A6:A10 > Data > Text to Columns > Delimited > Other: | (work on a copy first).
A16: Part B: import the CSV as a refreshable query
A17: 1. Save regional_targets.csv (sent with this workbook) to your computer.
A18: 2. Data > Get Data > From File > From Text/CSV > choose the file.
A19: 3. Check the preview (comma delimiter, Target detected as a number) > Load.
A20: 4. Excel adds a new sheet with a Table linked to the file. This is a query (Power Query).
A21: 5. Open the CSV in Notepad, change East from 7000 to 7500, save, then Data > Refresh All.
A22: 6. Compare each target with Q1 revenue on the 7 Multi-Sheet tab.
A24: Part C: internal data in a Table (structured references)
A25: The Data sheet is already a Table named SalesData (Ctrl+T makes one). Type these in any empty cell:
A26: =SUM(SalesData[Revenue]) | E26: Whole column by name; grows when rows are added
A27: =AVERAGE(SalesData[Units]) | E27: No cell addresses to maintain
A28: =SUMIFS(SalesData[Revenue],SalesData[Region],"West") | E28: Readable criteria

Sheet 5 Sort Filter
A1: 5. Sorting and filtering
A2: Guide topic 5. The list below is a static copy of Data so you can sort and filter freely without affecting other sheets.
A4: Practice list (values only) | H4: Criteria range (for Advanced Filter)
A5: Date | B5: Region | C5: Rep | D5: Product | E5: Units | F5: Revenue | H5: Region | I5: Revenue
A6: 46027 | B6: East | C6: Avery | D6: Laptop | E6: 4 | F6: 3600 | H6: West | I6: >2000
A7: 46034 | B7: West | C7: Blake | D7: Monitor | E7: 10 | F7: 2500 | H7: Same row = AND. A second criteria row would mean OR.
A8: 46041 | B8: North | C8: Casey | D8: Keyboard | E8: 25 | F8: 1000
A9: 46048 | B9: South | C9: Devon | D9: Mouse | E9: 40 | F9: 1000 | H9: Advanced Filter steps
A10: 46055 | B10: East | C10: Avery | D10: License | E10: 15 | F10: 1800 | H10: 1. Click any cell in A5:F25.
A11: 46062 | B11: West | C11: Blake | D11: Laptop | E11: 6 | F11: 5400 | H11: 2. Data > Advanced.
A12: 46069 | B12: North | C12: Casey | D12: Monitor | E12: 8 | F12: 2000 | H12: 3. List range: $A$5:$F$25
A13: 46076 | B13: South | C13: Devon | D13: Keyboard | E13: 30 | F13: 1200 | H13: 4. Criteria range: $H$5:$I$6
A14: 46083 | B14: East | C14: Avery | D14: Mouse | E14: 50 | F14: 1250 | H14: 5. Choose "Copy to another location", Copy to: $H$22
A15: 46090 | B15: West | C15: Blake | D15: License | E15: 20 | F15: 2400 | H15: 6. OK. You should get the 3 rows shown in the check.
A16: 46097 | B16: North | C16: Casey | D16: Laptop | E16: 3 | F16: 2700
A17: 46104 | B17: South | C17: Devon | D17: Monitor | E17: 12 | F17: 3000 | H17: Answer check: West orders over $2,000
A18: 46118 | B18: East | C18: Avery | D18: Keyboard | E18: 20 | F18: 800 | H18: Date | I18: Product | J18: Revenue
A19: 46125 | B19: West | C19: Blake | D19: Mouse | E19: 35 | F19: 875 | H19: 46034 | I19: Monitor | J19: 2500
A20: 46132 | B20: North | C20: Casey | D20: License | E20: 10 | F20: 1200 | H20: 46062 | I20: Laptop | J20: 5400
A21: 46139 | B21: South | C21: Devon | D21: Laptop | E21: 5 | F21: 4500 | H21: 46090 | I21: License | J21: 2400
A22: 46146 | B22: East | C22: Avery | D22: Monitor | E22: 9 | F22: 2250 | H22: Advanced Filter output lands here
A23: 46153 | B23: West | C23: Blake | D23: Keyboard | E23: 15 | F23: 600
A24: 46160 | B24: North | C24: Casey | D24: Mouse | E24: 60 | F24: 1500
A25: 46167 | B25: South | C25: Devon | D25: License | E25: 25 | F25: 3000
A28: Sort and AutoFilter
A29: Sort: Data > Sort > Sort by Region (A to Z) > Add Level > then by Revenue (Largest to Smallest).
A30: AutoFilter: Data > Filter, then use the Product arrow > untick Select All > tick Laptop.
A31: Number filter: Revenue arrow > Number Filters > Top 10 > change to Top 5.
A32: Clear: Data > Clear. Remove arrows: Data > Filter again.
A34: Dynamic array versions (Excel 365 / 2021)
A35: Type these in an empty area to the right. Each one spills into as many cells as it needs.
A36: =SORT(A6:F25,6,-1) | H36: Sort by the 6th column, descending
A37: =FILTER(A6:F25,(B6:B25="West")*(F6:F25>2000)) | H37: * means AND; the same 3 rows as the check
A38: =UNIQUE(B6:B25) | H38: The distinct regions

Sheet 6 Lookup Query
A1: 6. Extracting and querying data
A2: Guide topic 6. Lookups pull one matching value; database functions summarise every row that meets a criteria range.
A4: Product to look up | B4: Monitor | E4: Commission tiers
A5: Price with VLOOKUP (exact) | B5: =VLOOKUP(B4,Data!$K$5:$M$9,3,FALSE()) -> 250 | E5: Revenue from | F5: Rate | H5: =VLOOKUP(B4,Data!$K$5:$M$9,3,FALSE)
A6: Category with INDEX/MATCH | B6: =INDEX(Data!$L$5:$L$9,MATCH(B4,Data!$K$5:$K$9,0)) -> Hardware | E6: 0 | F6: 0.02 | H6: =INDEX(Data!$L$5:$L$9,MATCH(B4,Data!$K$5:$K$9,0))
A7: Price with XLOOKUP (type it yourself) | E7: 5000 | F7: 0.04 | H7: =XLOOKUP(B4,Data!K5:K9,Data!M5:M9,"Not found")
E8: 10000 | F8: 0.06
E9: Invented tiers; must be sorted ascending
A10: Rep revenue | B10: 9700
A11: Rate with VLOOKUP (approximate) | B11: =VLOOKUP(B10,$E$6:$F$8,2,TRUE()) -> 0.04 | H11: =VLOOKUP(B10,$E$6:$F$8,2,TRUE)
A12: Commission | B12: =B10*B11 -> 388
A14: Region | B14: West
A15: Category | B15: Hardware
A16: Two-way lookup: INDEX/MATCH/MATCH | B16: =INDEX('3 PivotTables'!$B$17:$D$20,MATCH(B14,'3 PivotTables'!$A$17:$A$20,0),MATCH(B15,'3 PivotTables'!$B$16:$D$16,0)) -> 7900 | H16: =INDEX('3 PivotTables'!$B$17:$D$20,MATCH(B14,'3 PivotTables'!$A$17:$A$20,0),MATCH(B15,'3 PivotTables'!$B$16:$D$16,0))
A19: Database functions | E19: Criteria range
A20: Total revenue of matching orders | B20: =DSUM(Data!$A$4:$H$24,"Revenue",$E$20:$F$21) -> 10300 | E20: Region | F20: Revenue | H20: =DSUM(Data!$A$4:$H$24,"Revenue",$E$20:$F$21)
A21: Number of matching orders | B21: =DCOUNT(Data!$A$4:$H$24,"Revenue",$E$20:$F$21) -> 3 | E21: West | F21: >2000 | H21: =DCOUNT(Data!$A$4:$H$24,"Revenue",$E$20:$F$21)
A22: Average matching order | B22: =DAVERAGE(Data!$A$4:$H$24,"Revenue",$E$20:$F$21) -> 3433.3333 | H22: =DAVERAGE(Data!$A$4:$H$24,"Revenue",$E$20:$F$21)
A23: Largest matching order | B23: =DMAX(Data!$A$4:$H$24,"Revenue",$E$20:$F$21) -> 5400 | H23: =DMAX(Data!$A$4:$H$24,"Revenue",$E$20:$F$21)
A24: Same total with SUMIFS | B24: =SUMIFS(Data!$H$5:$H$24,Data!$B$5:$B$24,E21,Data!$H$5:$H$24,F21) -> 10300 | H24: =SUMIFS(Data!$H$5:$H$24,Data!$B$5:$B$24,E21,Data!$H$5:$H$24,F21)
A27: Try it
A28: Change B4 to Laptop: price becomes $900 and category stays Hardware.
A29: Change B10 to 10000: the rate jumps to 6% because approximate match takes the last tier that is not above the value.
A30: Change E21 to South: all four database results update at once.

Sheet 7 Multi-Sheet
A1: 7. Models with multiple worksheets and workbooks
A2: Guide topic 7. Jan, Feb and Mar share one layout, so a 3-D reference can add the same cell across all three.
A4: Region | B4: Jan | C4: Feb | D4: Mar | E4: Q1 Revenue (3-D) | F4: Q1 Profit (3-D) | H4: Formulas used
A5: East | B5: =Jan!B5 -> 3600 | C5: =Feb!B5 -> 1800 | D5: =Mar!B5 -> 1250 | E5: =SUM(Jan:Mar!B5:B5) -> 6650 | F5: =SUM(Jan:Mar!D5:D5) -> 2550 | H5: =Jan!B5
A6: West | B6: =Jan!B6 -> 2500 | C6: =Feb!B6 -> 5400 | D6: =Mar!B6 -> 2400 | E6: =SUM(Jan:Mar!B6:B6) -> 10300 | F6: =SUM(Jan:Mar!D6:D6) -> 3900 | H6: =SUM(Jan:Mar!B6)
A7: North | B7: =Jan!B7 -> 1000 | C7: =Feb!B7 -> 2000 | D7: =Mar!B7 -> 2700 | E7: =SUM(Jan:Mar!B7:B7) -> 5700 | F7: =SUM(Jan:Mar!D7:D7) -> 2000
A8: South | B8: =Jan!B8 -> 1000 | C8: =Feb!B8 -> 1200 | D8: =Mar!B8 -> 3000 | E8: =SUM(Jan:Mar!B8:B8) -> 5200 | F8: =SUM(Jan:Mar!D8:D8) -> 1900
A9: Total | B9: =SUM(B5:B8) -> 8100 | C9: =SUM(C5:C8) -> 10400 | D9: =SUM(D5:D8) -> 9350 | E9: =SUM(E5:E8) -> 27850 | F9: =SUM(F5:F8) -> 10350
A12: Try it
A13: 1. Click E5 and press F2 to see the 3-D reference Jan:Mar!B5.
A14: 2. Drag the Feb tab so it sits to the right of Mar, then back. Totals are unchanged while Feb stays between Jan and Mar.
A15: 3. Group edit: click Jan, Shift+click Mar, type a note in F1. It appears on all three. Right-click > Ungroup Sheets.
A16: 4. Insert a new sheet between Jan and Mar with the same layout: the 3-D totals include it automatically.
A18: Linking to another workbook
A19: A link to another workbook looks like this (shown as text; red text is the convention for external links):
A20: ='[Budget2026.xlsx]Jan'!$B$9
A21: When the source is closed Excel shows the full path, e.g. ='C:\Reports\[Budget2026.xlsx]Jan'!$B$9
A22: Manage links: Data > Edit Links (Workbook Links) to update, change source or break a link.
A23: Data > Consolidate can also total ranges from several sheets or workbooks without writing formulas.

Sheet Jan
A1: Jan 2026 results
A2: Identical layout on Jan, Feb and Mar. Revenue matches the Data sheet; expenses are invented.
A4: Region | B4: Revenue | C4: Expenses | D4: Profit
A5: East | B5: 3600 | C5: 2200 | D5: =B5-C5 -> 1400
A6: West | B6: 2500 | C6: 1600 | D6: =B6-C6 -> 900
A7: North | B7: 1000 | C7: 700 | D7: =B7-C7 -> 300
A8: South | B8: 1000 | C8: 650 | D8: =B8-C8 -> 350
A9: Total | B9: =SUM(B5:B8) -> 8100 | C9: =SUM(C5:C8) -> 5150 | D9: =SUM(D5:D8) -> 2950

Sheet Feb
A1: Feb 2026 results
A2: Identical layout on Jan, Feb and Mar. Revenue matches the Data sheet; expenses are invented.
A4: Region | B4: Revenue | C4: Expenses | D4: Profit
A5: East | B5: 1800 | C5: 1100 | D5: =B5-C5 -> 700
A6: West | B6: 5400 | C6: 3300 | D6: =B6-C6 -> 2100
A7: North | B7: 2000 | C7: 1300 | D7: =B7-C7 -> 700
A8: South | B8: 1200 | C8: 800 | D8: =B8-C8 -> 400
A9: Total | B9: =SUM(B5:B8) -> 10400 | C9: =SUM(C5:C8) -> 6500 | D9: =SUM(D5:D8) -> 3900

Sheet Mar
A1: Mar 2026 results
A2: Identical layout on Jan, Feb and Mar. Revenue matches the Data sheet; expenses are invented.
A4: Region | B4: Revenue | C4: Expenses | D4: Profit
A5: East | B5: 1250 | C5: 800 | D5: =B5-C5 -> 450
A6: West | B6: 2400 | C6: 1500 | D6: =B6-C6 -> 900
A7: North | B7: 2700 | C7: 1700 | D7: =B7-C7 -> 1000
A8: South | B8: 3000 | C8: 1850 | D8: =B8-C8 -> 1150
A9: Total | B9: =SUM(B5:B8) -> 9350 | C9: =SUM(C5:C8) -> 5850 | D9: =SUM(D5:D8) -> 3500

Sheet 8 Auditing
A1: 8. Formula auditing
A2: Guide topic 8. Use Formulas > Formula Auditing on the model, then work through the error table and the bug hunt.
A4: Mini income model | D4: Auditing tools to try | G4: Test cells
A5: Units sold | B5: 500 | D5: 1. Click B14 > Formulas > Trace Precedents. Click again to go a level deeper. | G5: Zero cell | H5: 0
A6: Price per unit | B6: 20 | D6: 2. Click B5 > Trace Dependents to see everything Units feeds. | G6: Text cell | H6: abc
A7: Revenue | B7: =B5*B6 -> 10000 | D7: 3. Remove Arrows clears them.
A8: COGS % | B8: 0.6 | D8: 4. Ctrl + ` (grave accent) toggles Show Formulas.
A9: COGS | B9: =B7*B8 -> 6000 | D9: 5. Click B14 > Evaluate Formula > Evaluate to step through the calculation.
A10: Gross profit | B10: =B7-B9 -> 4000 | D10: 6. Watch Window > Add Watch > B14, then change B5 from another sheet.
A11: Operating expenses | B11: 2500
A12: Operating income | B12: =B10-B11 -> 1500
A13: Tax rate | B13: 0.25
A14: Net income | B14: =B12*(1-B13) -> 1125
A15: All model inputs are invented.
A18: Error table: type the broken formula in a spare cell, read the error, then compare with the fix
A19: Error (shown with a leading #) | B19: Fixed (live) | D19: Broken formula to type | E19: What causes it
A20: DIV/0! | B20: =IF(H5=0,"n/a",B7/H5) -> n/a | D20: =B7/H5 | E20: Dividing by zero or by an empty cell
A21: VALUE! | B21: =B7+N(H6) -> 10000 | D21: =B7+H6 | E21: Maths on text; N() turns text into 0
A22: N/A | B22: =IFERROR(VLOOKUP("Tablet",Data!$K$5:$M$9,3,FALSE()),"Not found") -> Not found | D22: =VLOOKUP("Tablet",Data!K5:M9,3,FALSE) | E22: Lookup value is not in the list
A23: NAME? | B23: =SUM(B5:B6) -> 520 | D23: =SUMM(B5:B6) | E23: Misspelled function or undefined name
A24: REF! | D24: =B7 then delete row 7 (then Undo!) | E24: The cell a formula pointed to was deleted
A25: ##### | D25: Narrow column B until numbers vanish | E25: Column too narrow: not really an error
A26: Circular | D26: Type =B14+1 into B14 (then Undo!) | E26: A formula that refers to its own cell
A29: Bug hunt: no error value, but the total is wrong. Why?
A30: Expense | B30: Amount
A31: Rent | B31: 1200 | D31: Click B35 > Trace Precedents: the blue box stops at row 33.
A32: Utilities | B32: 800 | D32: Excel also flags it with a green triangle: "Formula omits adjacent cells".
A33: Supplies | B33: 450
A34: Insurance | B34: 300
A35: Total (deliberately wrong) | B35: =SUM(B31:B33) -> 2450
A36: Correct total | B36: =SUM(B31:B34) -> 2750

Sheet 9 Input Control
A1: 9. Controlling user input
A2: Guide topic 9. Every yellow cell has a data validation rule. Try to break each one.
A4: Order form | D4: Cell | E4: Rule (Data > Data Validation) | F4: Try typing this
A5: Product | B5: Laptop | D5: B5 Product | E5: List, source =Data!$K$5:$K$9 | F5: Tablet (rejected)
A6: Quantity | B6: 3 | D6: B6 Quantity | E6: Whole number between 1 and 100 | F6: 0, 2.5 or 500 (all rejected)
A7: Order date | B7: 46303 | D7: B7 Order date | E7: Date >= DATE(2026,1,1) | F7: 12/31/2025 (rejected)
A8: Discount | B8: 0.1 | D8: B8 Discount | E8: Decimal 0 to 0.2, Warning style | F8: 0.5 (warning: you may continue)
A9: Customer code | B9: C1234 | D9: B9 Customer code | E9: Custom =AND(LEN(B9)=5,LEFT(B9,1)="C") | F9: X1234 or C12 (rejected)
A10: Rush order? | B10: No | D10: B10 Rush order? | E10: List typed in the box: Yes,No | F10: Maybe (rejected)
A12: Unit price | B12: =VLOOKUP(B5,Data!$K$5:$M$9,3,FALSE()) -> 900
A13: Order total | B13: =B6*B12*(1-B8) -> 2430
A16: Protect the sheet so only the inputs can change
A17: 1. The six yellow cells are already unlocked (Format Cells > Protection > Locked is unticked).
A18: 2. Review > Protect Sheet > OK (a password is optional).
A19: 3. Now try to type over B13: Excel refuses. The yellow cells still accept input.
A20: 4. Review > Unprotect Sheet to switch it off.
A21: 5. Data > Data Validation > Circle Invalid Data highlights entries that broke a rule before it existed.

Sheet 10 Financial
A1: 10. Financial functions
A2: Guide topic 10. Money you pay out is negative, money you receive is positive. Rate and periods must use the same time unit.
F3: Amortization schedule
A4: Loan amount | B4: 25000 | C4: Loan inputs are invented | F4: Period | G4: Beginning | H4: Payment | I4: Interest | J4: Principal | K4: Ending
A5: Annual interest rate | B5: 0.06 | F5: 1 | G5: =$B$4 -> 25000 | H5: =$B$9 -> 483.32004 | I5: =G5*$B$5/$B$7 -> 125 | J5: =H5-I5 -> 358.32004 | K5: =G5-J5 -> 24641.68
A6: Term (years) | B6: 5 | F6: 2 | G6: =K5 -> 24641.68 | H6: =$B$9 -> 483.32004 | I6: =G6*$B$5/$B$7 -> 123.2084 | J6: =H6-I6 -> 360.11164 | K6: =G6-J6 -> 24281.568
A7: Payments per year | B7: 12 | F7: 3 | G7: =K6 -> 24281.568 | H7: =$B$9 -> 483.32004 | I7: =G7*$B$5/$B$7 -> 121.40784 | J7: =H7-I7 -> 361.9122 | K7: =G7-J7 -> 23919.656
A8: Loan results | F8: 4 | G8: =K7 -> 23919.656 | H8: =$B$9 -> 483.32004 | I8: =G8*$B$5/$B$7 -> 119.59828 | J8: =H8-I8 -> 363.72176 | K8: =G8-J8 -> 23555.934
A9: Monthly payment | B9: =PMT(B5/B7,B6*B7,-B4) -> 483.32004 | C9: =PMT(B5/B7,B6*B7,-B4) | F9: 5 | G9: =K8 -> 23555.934 | H9: =$B$9 -> 483.32004 | I9: =G9*$B$5/$B$7 -> 117.77967 | J9: =H9-I9 -> 365.54037 | K9: =G9-J9 -> 23190.394
A10: Total paid | B10: =B9*B6*B7 -> 28999.202 | C10: =B9*B6*B7 | F10: 6 | G10: =K9 -> 23190.394 | H10: =$B$9 -> 483.32004 | I10: =G10*$B$5/$B$7 -> 115.95197 | J10: =H10-I10 -> 367.36807 | K10: =G10-J10 -> 22823.026
A11: Total interest | B11: =B10-B4 -> 3999.2023 | C11: =B10-B4 | F11: 7 | G11: =K10 -> 22823.026 | H11: =$B$9 -> 483.32004 | I11: =G11*$B$5/$B$7 -> 114.11513 | J11: =H11-I11 -> 369.20491 | K11: =G11-J11 -> 22453.821
A12: Interest in payment 1 | B12: =IPMT(B5/B7,1,B6*B7,-B4) -> 125 | C12: =IPMT(B5/B7,1,B6*B7,-B4) | F12: 8 | G12: =K11 -> 22453.821 | H12: =$B$9 -> 483.32004 | I12: =G12*$B$5/$B$7 -> 112.26911 | J12: =H12-I12 -> 371.05093 | K12: =G12-J12 -> 22082.77
A13: Principal in payment 1 | B13: =PPMT(B5/B7,1,B6*B7,-B4) -> 358.32004 | C13: =PPMT(B5/B7,1,B6*B7,-B4) | F13: 9 | G13: =K12 -> 22082.77 | H13: =$B$9 -> 483.32004 | I13: =G13*$B$5/$B$7 -> 110.41385 | J13: =H13-I13 -> 372.90619 | K13: =G13-J13 -> 21709.864
A14: Check: number of payments | B14: =NPER(B5/B7,-B9,B4) -> 60 | C14: =NPER(B5/B7,-B9,B4) | F14: 10 | G14: =K13 -> 21709.864 | H14: =$B$9 -> 483.32004 | I14: =G14*$B$5/$B$7 -> 108.54932 | J14: =H14-I14 -> 374.77072 | K14: =G14-J14 -> 21335.093
A15: Check: annual rate | B15: =RATE(B6*B7,-B9,B4)*B7 -> 0.06 | C15: =RATE(B6*B7,-B9,B4)*B7 | F15: 11 | G15: =K14 -> 21335.093 | H15: =$B$9 -> 483.32004 | I15: =G15*$B$5/$B$7 -> 106.67547 | J15: =H15-I15 -> 376.64457 | K15: =G15-J15 -> 20958.449
F16: 12 | G16: =K15 -> 20958.449 | H16: =$B$9 -> 483.32004 | I16: =G16*$B$5/$B$7 -> 104.79224 | J16: =H16-I16 -> 378.5278 | K16: =G16-J16 -> 20579.921
A17: Saving for a goal (FV) | F17: 13 | G17: =K16 -> 20579.921 | H17: =$B$9 -> 483.32004 | I17: =G17*$B$5/$B$7 -> 102.8996 | J17: =H17-I17 -> 380.42043 | K17: =G17-J17 -> 20199.5
A18: Monthly deposit | B18: 200 | F18: 14 | G18: =K17 -> 20199.5 | H18: =$B$9 -> 483.32004 | I18: =G18*$B$5/$B$7 -> 100.9975 | J18: =H18-I18 -> 382.32254 | K18: =G18-J18 -> 19817.178
A19: Annual return | B19: 0.05 | F19: 15 | G19: =K18 -> 19817.178 | H19: =$B$9 -> 483.32004 | I19: =G19*$B$5/$B$7 -> 99.085889 | J19: =H19-I19 -> 384.23415 | K19: =G19-J19 -> 19432.944
A20: Years | B20: 10 | F20: 16 | G20: =K19 -> 19432.944 | H20: =$B$9 -> 483.32004 | I20: =G20*$B$5/$B$7 -> 97.164718 | J20: =H20-I20 -> 386.15532 | K20: =G20-J20 -> 19046.788
A21: Future value of the savings | B21: =FV(B19/12,B20*12,-B18) -> 31056.456 | C21: =FV(B19/12,B20*12,-B18) | F21: 17 | G21: =K20 -> 19046.788 | H21: =$B$9 -> 483.32004 | I21: =G21*$B$5/$B$7 -> 95.233942 | J21: =H21-I21 -> 388.0861 | K21: =G21-J21 -> 18658.702
F22: 18 | G22: =K21 -> 18658.702 | H22: =$B$9 -> 483.32004 | I22: =G22*$B$5/$B$7 -> 93.293511 | J22: =H22-I22 -> 390.02653 | K22: =G22-J22 -> 18268.676
A23: Value today of future money (PV) | F23: 19 | G23: =K22 -> 18268.676 | H23: =$B$9 -> 483.32004 | I23: =G23*$B$5/$B$7 -> 91.343379 | J23: =H23-I23 -> 391.97666 | K23: =G23-J23 -> 17876.699
A24: Amount received in the future | B24: 10000 | F24: 20 | G24: =K23 -> 17876.699 | H24: =$B$9 -> 483.32004 | I24: =G24*$B$5/$B$7 -> 89.383495 | J24: =H24-I24 -> 393.93654 | K24: =G24-J24 -> 17482.763
A25: Years until received | B25: 5 | F25: 21 | G25: =K24 -> 17482.763 | H25: =$B$9 -> 483.32004 | I25: =G25*$B$5/$B$7 -> 87.413813 | J25: =H25-I25 -> 395.90623 | K25: =G25-J25 -> 17086.856
A26: Discount rate | B26: 0.05 | F26: 22 | G26: =K25 -> 17086.856 | H26: =$B$9 -> 483.32004 | I26: =G26*$B$5/$B$7 -> 85.434282 | J26: =H26-I26 -> 397.88576 | K26: =G26-J26 -> 16688.971
A27: Present value today | B27: =PV(B26,B25,0,-B24) -> 7835.2617 | C27: =PV(B26,B25,0,-B24) | F27: 23 | G27: =K26 -> 16688.971 | H27: =$B$9 -> 483.32004 | I27: =G27*$B$5/$B$7 -> 83.444853 | J27: =H27-I27 -> 399.87519 | K27: =G27-J27 -> 16289.095
F28: 24 | G28: =K27 -> 16289.095 | H28: =$B$9 -> 483.32004 | I28: =G28*$B$5/$B$7 -> 81.445477 | J28: =H28-I28 -> 401.87456 | K28: =G28-J28 -> 15887.221
A29: Evaluating a project (NPV and IRR) | F29: 25 | G29: =K28 -> 15887.221 | H29: =$B$9 -> 483.32004 | I29: =G29*$B$5/$B$7 -> 79.436104 | J29: =H29-I29 -> 403.88393 | K29: =G29-J29 -> 15483.337
A30: Discount rate | B30: 0.08 | F30: 26 | G30: =K29 -> 15483.337 | H30: =$B$9 -> 483.32004 | I30: =G30*$B$5/$B$7 -> 77.416684 | J30: =H30-I30 -> 405.90335 | K30: =G30-J30 -> 15077.434
A31: Year 0 (investment) | B31: -10000 | F31: 27 | G31: =K30 -> 15077.434 | H31: =$B$9 -> 483.32004 | I31: =G31*$B$5/$B$7 -> 75.387168 | J31: =H31-I31 -> 407.93287 | K31: =G31-J31 -> 14669.501
A32: Year 1 | B32: 3000 | F32: 28 | G32: =K31 -> 14669.501 | H32: =$B$9 -> 483.32004 | I32: =G32*$B$5/$B$7 -> 73.347503 | J32: =H32-I32 -> 409.97253 | K32: =G32-J32 -> 14259.528
A33: Year 2 | B33: 4000 | F33: 29 | G33: =K32 -> 14259.528 | H33: =$B$9 -> 483.32004 | I33: =G33*$B$5/$B$7 -> 71.297641 | J33: =H33-I33 -> 412.0224 | K33: =G33-J33 -> 13847.506
A34: Year 3 | B34: 4000 | F34: 30 | G34: =K33 -> 13847.506 | H34: =$B$9 -> 483.32004 | I34: =G34*$B$5/$B$7 -> 69.237529 | J34: =H34-I34 -> 414.08251 | K34: =G34-J34 -> 13433.423
A35: Year 4 | B35: 3000 | F35: 31 | G35: =K34 -> 13433.423 | H35: =$B$9 -> 483.32004 | I35: =G35*$B$5/$B$7 -> 67.167116 | J35: =H35-I35 -> 416.15292 | K35: =G35-J35 -> 13017.27
A36: Net present value | B36: =NPV(B30,B32:B35)+B31 -> 1587.5516 | C36: =NPV(B30,B32:B35)+B31 NPV starts at year 1, so add year 0 separately | F36: 32 | G36: =K35 -> 13017.27 | H36: =$B$9 -> 483.32004 | I36: =G36*$B$5/$B$7 -> 65.086352 | J36: =H36-I36 -> 418.23369 | K36: =G36-J36 -> 12599.037
A37: Internal rate of return | B37: =IRR(B31:B35) -> 0.14895028 | C37: =IRR(B31:B35) | F37: 33 | G37: =K36 -> 12599.037 | H37: =$B$9 -> 483.32004 | I37: =G37*$B$5/$B$7 -> 62.995183 | J37: =H37-I37 -> 420.32486 | K37: =G37-J37 -> 12178.712
F38: 34 | G38: =K37 -> 12178.712 | H38: =$B$9 -> 483.32004 | I38: =G38*$B$5/$B$7 -> 60.893559 | J38: =H38-I38 -> 422.42648 | K38: =G38-J38 -> 11756.285
A39: Depreciation (SLN) | F39: 35 | G39: =K38 -> 11756.285 | H39: =$B$9 -> 483.32004 | I39: =G39*$B$5/$B$7 -> 58.781426 | J39: =H39-I39 -> 424.53861 | K39: =G39-J39 -> 11331.747
A40: Asset cost | B40: 10000 | F40: 36 | G40: =K39 -> 11331.747 | H40: =$B$9 -> 483.32004 | I40: =G40*$B$5/$B$7 -> 56.658733 | J40: =H40-I40 -> 426.6613 | K40: =G40-J40 -> 10905.085
...

Sheet 11 Solver Linear
A1: 11. Solver: linear optimization
A2: Guide topic 11. A furniture maker chooses how many tables and chairs to build to maximise profit. Numbers are invented.
B4: Tables | C4: Chairs
A5: Units to make (changing cells) | B5: 0 | C5: 0
A6: Profit per unit | B6: 50 | C6: 30
A8: Total profit (objective) | B8: =SUMPRODUCT(B5:C5,B6:C6) -> 0
A10: Resource (hours per unit) | B10: Tables | C10: Chairs | D10: Used | F10: Available
A11: Carpentry hours | B11: 4 | C11: 3 | D11: =SUMPRODUCT($B$5:$C$5,B11:C11) -> 0 | E11: <= | F11: 240
A12: Finishing hours | B12: 2 | C12: 1 | D12: =SUMPRODUCT($B$5:$C$5,B12:C12) -> 0 | E12: <= | F12: 100
A15: Solver setup
A16: 0. One-time setup: File > Options > Add-ins > Manage: Excel Add-ins > Go > tick Solver Add-in.
A17: 1. Data > Solver.
A18: 2. Set Objective: $B$8 To: Max
A19: 3. By Changing Variable Cells: $B$5:$C$5
A20: 4. Add constraint: $D$11:$D$12 <= $F$11:$F$12
A21: 5. Tick "Make Unconstrained Variables Non-Negative".
A22: 6. Select a Solving Method: Simplex LP.
A23: 7. Solve > Keep Solver Solution. Tick Answer and Sensitivity reports to see them on new sheets.
A25: Answer check
A26: Tables | B26: 30
A27: Chairs | B27: 40
A28: Maximum profit | B28: =B26*B6+B27*C6 -> 2700
A29: Both resources are fully used at the optimum (binding constraints).

Sheet 12 Solver Nonlinear
A1: 12. Solver: nonlinear optimization
A2: Guide topic 12. Demand falls as price rises, so profit is a curve. Solver finds the top of it. Numbers are invented.
A4: Price (changing cell) | B4: 10 | D4: Price | E4: Profit
A5: Unit cost | B5: 6 | D5: 6 | E5: =(D5-$B$5)*($B$7-$B$8*D5)-$B$6 -> -2000
A6: Fixed cost | B6: 2000 | D6: 10 | E6: =(D6-$B$5)*($B$7-$B$8*D6)-$B$6 -> 1200
A7: Demand at price 0 | B7: 1200 | D7: 14 | E7: =(D7-$B$5)*($B$7-$B$8*D7)-$B$6 -> 3120
A8: Units lost per $1 of price | B8: 40 | D8: 18 | E8: =(D8-$B$5)*($B$7-$B$8*D8)-$B$6 -> 3760
D9: 22 | E9: =(D9-$B$5)*($B$7-$B$8*D9)-$B$6 -> 3120
A10: Demand (units) | B10: =B7-B8*B4 -> 800 | D10: 26 | E10: =(D10-$B$5)*($B$7-$B$8*D10)-$B$6 -> 1200
A11: Revenue | B11: =B4*B10 -> 8000 | D11: 30 | E11: =(D11-$B$5)*($B$7-$B$8*D11)-$B$6 -> -2000
A12: Total cost | B12: =B6+B5*B10 -> 6800
A13: Profit (objective) | B13: =B11-B12 -> 1200
A16: Solver setup
A17: 1. Data > Solver.
A18: 2. Set Objective: $B$13 To: Max
A19: 3. By Changing Variable Cells: $B$4
A20: 4. Add constraints: $B$4 >= $B$5 and $B$4 <= 30
A21: 5. Select a Solving Method: GRG Nonlinear (price times demand makes the model nonlinear).
A22: 6. Solve. Then start again from price 28 and solve: a smooth single-peak curve gives the same answer.
A23: 7. For bumpy models tick Options > GRG Nonlinear > Use Multistart, or try Evolutionary.
A25: Answer check
A26: Best price | B26: =(B7/B8+B5)/2 -> 18
A27: Profit at best price | B27: =(B26-B5)*(B7-B8*B26)-B6 -> 3760
A28: Calculus check: profit peaks halfway between unit cost and the price where demand hits zero.

Sheet 13 Data Tables
A1: 13. One- and two-variable data tables
A2: Guide topic 13. A data table reruns one formula for a list of input values. Fill the yellow areas with Data > What-If Analysis > Data Table.
A4: Loan amount | B4: 25000
A5: Annual rate | B5: 0.06
A6: Years | B6: 5
A7: Monthly payment | B7: =PMT(B5/12,B6*12,-B4) -> 483.32004
A9: One-variable table: payment at different rates | D9: Answer check
A10: Rate | B10: =B7 -> 483.32004 | F10: 1. Select A10:B15
A11: 0.04 | D11: =PMT(A11/12,$B$6*12,-$B$4) -> 460.41305 | F11: 2. Data > What-If Analysis > Data Table
A12: 0.05 | D12: =PMT(A12/12,$B$6*12,-$B$4) -> 471.78084 | F12: 3. Leave Row input cell empty
A13: 0.06 | D13: =PMT(A13/12,$B$6*12,-$B$4) -> 483.32004 | F13: 4. Column input cell: $B$5 > OK
A14: 0.07 | D14: =PMT(A14/12,$B$6*12,-$B$4) -> 495.02996 | F14: B11:B15 should equal the green column.
A15: 0.08 | D15: =PMT(A15/12,$B$6*12,-$B$4) -> 506.90986
A18: Two-variable table: payment by rate (down) and years (across) | F18: Answer check
A19: =B7 -> 483.32004 | B19: 3 | C19: 4 | D19: 5 | F19: =B19 -> 3 | G19: =C19 -> 4 | H19: =D19 -> 5
A20: 0.04 | F20: =PMT($A20/12,F$19*12,-$B$4) -> 738.09963 | G20: =PMT($A20/12,G$19*12,-$B$4) -> 564.47637 | H20: =PMT($A20/12,H$19*12,-$B$4) -> 460.41305
A21: 0.05 | F21: =PMT($A21/12,F$19*12,-$B$4) -> 749.27243 | G21: =PMT($A21/12,G$19*12,-$B$4) -> 575.73234 | H21: =PMT($A21/12,H$19*12,-$B$4) -> 471.78084
A22: 0.06 | F22: =PMT($A22/12,F$19*12,-$B$4) -> 760.54844 | G22: =PMT($A22/12,G$19*12,-$B$4) -> 587.12573 | H22: =PMT($A22/12,H$19*12,-$B$4) -> 483.32004
A23: 0.07 | F23: =PMT($A23/12,F$19*12,-$B$4) -> 771.92742 | G23: =PMT($A23/12,G$19*12,-$B$4) -> 598.65612 | H23: =PMT($A23/12,H$19*12,-$B$4) -> 495.02996
A24: 0.08 | F24: =PMT($A24/12,F$19*12,-$B$4) -> 783.40914 | G24: =PMT($A24/12,G$19*12,-$B$4) -> 610.32306 | H24: =PMT($A24/12,H$19*12,-$B$4) -> 506.90986
A27: Two-variable steps
A28: 1. Select A19:D24 (the formula sits in the top-left corner).
A29: 2. Data > What-If Analysis > Data Table.
A30: 3. Row input cell: $B$6 (the years run across the top row).
A31: 4. Column input cell: $B$5 (the rates run down the left column) > OK.
A32: 5. Click B20: the formula bar shows {=TABLE(B6,B5)}. You cannot edit one result cell on its own.

Sheet 14 Scenarios
A1: 14. Scenario management
A2: Guide topic 14. Save sets of input values as named scenarios and switch between them. Numbers are invented.
A4: Units sold | B4: 1000 | D4: Scenario | E4: Units | F4: Price | G4: Unit cost | H4: Expected profit
A5: Price | B5: 50 | D5: Best | E5: 1200 | F5: 52 | G5: 28 | H5: =E5*(F5-G5)-$B$7 -> 13800
A6: Unit cost | B6: 30 | D6: Base | E6: 1000 | F6: 50 | G6: 30 | H6: =E6*(F6-G6)-$B$7 -> 5000
A7: Fixed costs | B7: 15000 | D7: Worst | E7: 800 | F7: 48 | G7: 32 | H7: =E7*(F7-G7)-$B$7 -> -2200
A9: Revenue | B9: =B4*B5 -> 50000
A10: Total cost | B10: =B7+B4*B6 -> 45000
A11: Profit | B11: =B9-B10 -> 5000
A14: Scenario Manager steps
A15: 1. Data > What-If Analysis > Scenario Manager > Add.
A16: 2. Scenario name: Best Changing cells: $B$4:$B$6 > OK.
A17: 3. Enter 1200, 52 and 28 > Add. Repeat for Base and Worst using the table above > OK.
A18: 4. Pick a scenario > Show. Profit in B11 should equal the green check for that scenario.
A19: 5. Summary > Result cells: $B$11 > OK. Excel builds a Scenario Summary sheet comparing all three.
A20: 6. Tip: name the cells first (Formulas > Define Name) so the summary shows names, not addresses.
A22: Goal Seek: how many units to break even?
A23: 1. Show the Base scenario (1000, 50, 30).
A24: 2. Data > What-If Analysis > Goal Seek.
A25: 3. Set cell: $B$11 To value: 0 By changing cell: $B$4 > OK.
A26: Answer check: break-even units | B26: =B7/(F6-G6) -> 750

Sheet 15 Macros
A1: 15. Excel macros
A2: Guide topic 15. First: File > Save As > Excel Macro-Enabled Workbook (*.xlsm). An .xlsx file discards macros when saved.
A4: Record your first macro | C4: Order | D4: Revenue
A5: 0. Show the Developer tab: File > Options > Customize Ribbon > tick Developer. | C5: 1 | D5: =Data!H5 -> 3600
A6: 1. Select C4:D4. Developer > Record Macro. Name: FormatHeader, Shortcut: Ctrl+Shift+H, Store in: This Workbook. | C6: 2 | D6: =Data!H6 -> 2500
A7: 2. Make the cells bold, fill them green, centre them. Developer > Stop Recording. | C7: 3 | D7: =Data!H7 -> 1000
A8: 3. Select any other cells and press Ctrl+Shift+H to replay it. | C8: 4 | D8: =Data!H8 -> 1000
A9: 4. Developer > Macros > FormatHeader > Edit opens the VBA editor (Alt+F11) with the code Excel wrote. | C9: 5 | D9: =Data!H9 -> 1800
A10: 5. Use Relative References (toggle before recording) makes a macro act from the active cell instead of fixed addresses.
A12: Three short procedures to paste
A13: Alt+F11 > Insert > Module, then type or paste the code below. Run with F5 or Developer > Macros.
A14: Sub FormatHeader()
A15: ' Formats whatever cells are selected as a header row
A16: With Selection
A17: .Font.Bold = True
A18: .Font.Color = vbWhite
A19: .Interior.Color = RGB(33, 115, 70)
A20: .HorizontalAlignment = xlCenter
A21: End With
A22: End Sub
... A41: Security: File > Options > Trust Center > Macro Settings. Only enable macros in files you trust.
